<?xml version="1.0" ?>
<robot name="Chaser">
  <material name="Grey">
    <color rgba="0.2 0.2 0.2 1.0"/>
  </material>
  <material name="Orange">
    <color rgba="1.0 0.423529411765 0.0392156862745 1.0"/>
  </material>
  <material name="Blue">
  <color rgba="0.5 0.7 1.0 1.0"/>      
  </material>
  <material name="Red">
    <color rgba="1 0 0 1.0"/>      
  </material>

  <link name='base_link'/>

  <joint name="Joint_1" type="continuous">
    <parent link="base_link"/>
    <child link="Link_1"/>
    <origin rpy="0 0 0" xyz="0 0 0.0"/>
    <axis xyz="1 0 0"/>
  </joint>

  <link name="Link_1">
    <inertial>
      <origin rpy="0 0 0" xyz="0 0 0.0"/>
      <mass value="10"/>
      <inertia ixx="0.1" ixy="0" ixz="0" iyy="0.1" iyz="0" izz="0.1"/>
    </inertial>
    <visual>
      <origin rpy="0 0 0" xyz="0 0 0.375"/>
      <geometry>
        <cylinder radius="0.05" length="0.75"/>
      </geometry>
      <material name="Orange"/>
    </visual>

    <collision>
      <origin rpy="0 0 0" xyz="0 0 0.375"/>
      <geometry>
        <cylinder radius="0.05" length="0.75"/>
      </geometry>
    </collision>

    <visual>
      <origin rpy="0 1.5708 0" xyz="0 0 0"/>
      <geometry>
        <cylinder radius="0.075" length="0.15"/>
      </geometry>
      <material name="Orange"/>
    </visual>

    <collision>
      <origin rpy="0 1.5708 0" xyz="0 0 0"/>
      <geometry>
        <cylinder radius="0.075" length="0.15"/>
      </geometry>
    </collision>
  </link>

  <joint name="Joint_2" type="continuous">
    <parent link="Link_1"/>
    <child link="Link_2"/>
    <origin rpy="0 0 0" xyz="0 0 0.75"/>
    <axis xyz="1 0 0"/>
  </joint>

  <link name="Link_2">
    <inertial>
      <origin rpy="0 0 0" xyz="0 0 0.375"/>
      <mass value="10"/>
      <inertia ixx="0.1" ixy="0" ixz="0" iyy="0.1" iyz="0" izz="0.1"/>
    </inertial>

    <visual>
      <origin rpy="0 0 0" xyz="0 0 0.375"/>
      <geometry>
        <cylinder radius="0.05" length="0.75"/>
      </geometry>
      <material name="Orange"/>
    </visual>

    <collision>
      <origin rpy="0 0 0" xyz="0 0 0.375"/>
      <geometry>
        <cylinder radius="0.05" length="0.75"/>
      </geometry>
    </collision>

    <visual>
      <origin rpy="0 1.5708 0" xyz="0 0 0"/>
      <geometry>
        <cylinder radius="0.075" length="0.15"/>
      </geometry>
      <material name="Orange"/>
    </visual>

    <collision>
      <origin rpy="0 1.5708 0" xyz="0 0 0"/>
      <geometry>
        <cylinder radius="0.075" length="0.15"/>
      </geometry>
    </collision>
  </link>
</robot>